Workbook
Name esl_att: ESL!$G$5:$G$34
Name esl_pro: ESL!$H$5:$J$34
Name math_att: Maths!$G$5:$G$34
Name math_pro: Maths!$H$5:$H$34
Name sci_att: Science!$G$5:$G$34
Name sci_pro: Science!$H$5:$H$34

Sheet CLASS
A1: ROYAL INTERNATIONAL BILINGUAL SCHOOL ACADEMIC YEAR: 2026 - 2027
A2: CAMBRIDGE REPORT
A3: CLASS | C3: Student Name | E3: ESL | N3: SCIENCE | W3: MATHS
A4: STT | B4: Student ID | C4: Name (VN) | D4: Name (ENG) | E4: Attainment Score | F4: Progression Test Score | G4: Overall Score | H4: Graded | I4: Confident | J4: Responsible | K4: Reflective | L4: Innovative | M4: Engaged | N4: Attainment Score | O4: Progression Test Score | P4: Overall Score | Q4: Graded | R4: Confident | S4: Responsible | T4: Reflective | U4: Innovative | V4: Engaged | W4: Attainment Score | X4: Progression Test Score | Y4: Overall Score | Z4: Graded | AA4: Confident | AB4: Responsible | AC4: Reflective | AD4: Innovative | AE4: Engaged
A5: 1 | E5: =ESL!G5 -> 0 | F5: =ESL!K5 -> #DIV/0! | G5: =ESL!L5 -> #DIV/0! | H5: =IF(G5>=90.5,"A*",IF(G5>=79.5,"A",IF(G5>=64.5,"B",IF(G5>=49.5,"C",IF(G5>=34.5,"D","E"))))) -> #DIV/0! | I5: =ESL!M5 -> 0 | J5: =ESL!N5 -> 0 | K5: =ESL!O5 -> 0 | L5: =ESL!P5 -> 0 | M5: =ESL!Q5 -> 0 | N5: =Science!G5 -> 0 | O5: =Science!H5 -> 0 | P5: =Science!I5 -> 0 | Q5: =IF(P5>=90.5,"A*",IF(P5>=79.5,"A",IF(P5>=64.5,"B",IF(P5>=49.5,"C",IF(P5>=34.5,"D","E"))))) -> E | R5: =Science!J5 -> 0 | S5: =Science!K5 -> 0 | T5: =Science!L5 -> 0 | U5: =Science!M5 -> 0 | V5: =Science!N5 -> 0 | W5: =Maths!G5 -> 0 | X5: =Maths!H5 -> 0 | Y5: =Maths!I5 -> 0 | Z5: =IF(Y5>=90.5,"A*",IF(Y5>=79.5,"A",IF(Y5>=64.5,"B",IF(Y5>=49.5,"C",IF(Y5>=34.5,"D","E"))))) -> E | AA5: =Maths!J5 -> 0 | AB5: =Maths!K5 -> 0 | AC5: =Maths!L5 -> 0 | AD5: =Maths!M5 -> 0 | AE5: =Maths!N5 -> 0
A6: 2 | E6: =ESL!G6 -> 0 | F6: =ESL!K6 -> #DIV/0! | G6: =ESL!L6 -> #DIV/0! | H6: =IF(G6>=90.5,"A*",IF(G6>=79.5,"A",IF(G6>=64.5,"B",IF(G6>=49.5,"C",IF(G6>=34.5,"D","E"))))) -> #DIV/0! | I6: =ESL!M6 -> 0 | J6: =ESL!N6 -> 0 | K6: =ESL!O6 -> 0 | L6: =ESL!P6 -> 0 | M6: =ESL!Q6 -> 0 | N6: =Science!G6 -> 0 | O6: =Science!H6 -> 0 | P6: =Science!I6 -> 0 | Q6: =IF(P6>=90.5,"A*",IF(P6>=79.5,"A",IF(P6>=64.5,"B",IF(P6>=49.5,"C",IF(P6>=34.5,"D","E"))))) -> E | R6: =Science!J6 -> 0 | S6: =Science!K6 -> 0 | T6: =Science!L6 -> 0 | U6: =Science!M6 -> 0 | V6: =Science!N6 -> 0 | W6: =Maths!G6 -> 0 | X6: =Maths!H6 -> 0 | Y6: =Maths!I6 -> 0 | Z6: =IF(Y6>=90.5,"A*",IF(Y6>=79.5,"A",IF(Y6>=64.5,"B",IF(Y6>=49.5,"C",IF(Y6>=34.5,"D","E"))))) -> E | AA6: =Maths!J6 -> 0 | AB6: =Maths!K6 -> 0 | AC6: =Maths!L6 -> 0 | AD6: =Maths!M6 -> 0 | AE6: =Maths!N6 -> 0
A7: 3 | E7: =ESL!G7 -> 0 | F7: =ESL!K7 -> #DIV/0! | G7: =ESL!L7 -> #DIV/0! | H7: =IF(G7>=90.5,"A*",IF(G7>=79.5,"A",IF(G7>=64.5,"B",IF(G7>=49.5,"C",IF(G7>=34.5,"D","E"))))) -> #DIV/0! | I7: =ESL!M7 -> 0 | J7: =ESL!N7 -> 0 | K7: =ESL!O7 -> 0 | L7: =ESL!P7 -> 0 | M7: =ESL!Q7 -> 0 | N7: =Science!G7 -> 0 | O7: =Science!H7 -> 0 | P7: =Science!I7 -> 0 | Q7: =IF(P7>=90.5,"A*",IF(P7>=79.5,"A",IF(P7>=64.5,"B",IF(P7>=49.5,"C",IF(P7>=34.5,"D","E"))))) -> E | R7: =Science!J7 -> 0 | S7: =Science!K7 -> 0 | T7: =Science!L7 -> 0 | U7: =Science!M7 -> 0 | V7: =Science!N7 -> 0 | W7: =Maths!G7 -> 0 | X7: =Maths!H7 -> 0 | Y7: =Maths!I7 -> 0 | Z7: =IF(Y7>=90.5,"A*",IF(Y7>=79.5,"A",IF(Y7>=64.5,"B",IF(Y7>=49.5,"C",IF(Y7>=34.5,"D","E"))))) -> E | AA7: =Maths!J7 -> 0 | AB7: =Maths!K7 -> 0 | AC7: =Maths!L7 -> 0 | AD7: =Maths!M7 -> 0 | AE7: =Maths!N7 -> 0
A8: 4 | E8: =ESL!G8 -> 0 | F8: =ESL!K8 -> #DIV/0! | G8: =ESL!L8 -> #DIV/0! | H8: =IF(G8>=90.5,"A*",IF(G8>=79.5,"A",IF(G8>=64.5,"B",IF(G8>=49.5,"C",IF(G8>=34.5,"D","E"))))) -> #DIV/0! | I8: =ESL!M8 -> 0 | J8: =ESL!N8 -> 0 | K8: =ESL!O8 -> 0 | L8: =ESL!P8 -> 0 | M8: =ESL!Q8 -> 0 | N8: =Science!G8 -> 0 | O8: =Science!H8 -> 0 | P8: =Science!I8 -> 0 | Q8: =IF(P8>=90.5,"A*",IF(P8>=79.5,"A",IF(P8>=64.5,"B",IF(P8>=49.5,"C",IF(P8>=34.5,"D","E"))))) -> E | R8: =Science!J8 -> 0 | S8: =Science!K8 -> 0 | T8: =Science!L8 -> 0 | U8: =Science!M8 -> 0 | V8: =Science!N8 -> 0 | W8: =Maths!G8 -> 0 | X8: =Maths!H8 -> 0 | Y8: =Maths!I8 -> 0 | Z8: =IF(Y8>=90.5,"A*",IF(Y8>=79.5,"A",IF(Y8>=64.5,"B",IF(Y8>=49.5,"C",IF(Y8>=34.5,"D","E"))))) -> E | AA8: =Maths!J8 -> 0 | AB8: =Maths!K8 -> 0 | AC8: =Maths!L8 -> 0 | AD8: =Maths!M8 -> 0 | AE8: =Maths!N8 -> 0
A9: 5 | E9: =ESL!G9 -> 0 | F9: =ESL!K9 -> #DIV/0! | G9: =ESL!L9 -> #DIV/0! | H9: =IF(G9>=90.5,"A*",IF(G9>=79.5,"A",IF(G9>=64.5,"B",IF(G9>=49.5,"C",IF(G9>=34.5,"D","E"))))) -> #DIV/0! | I9: =ESL!M9 -> 0 | J9: =ESL!N9 -> 0 | K9: =ESL!O9 -> 0 | L9: =ESL!P9 -> 0 | M9: =ESL!Q9 -> 0 | N9: =Science!G9 -> 0 | O9: =Science!H9 -> 0 | P9: =Science!I9 -> 0 | Q9: =IF(P9>=90.5,"A*",IF(P9>=79.5,"A",IF(P9>=64.5,"B",IF(P9>=49.5,"C",IF(P9>=34.5,"D","E"))))) -> E | R9: =Science!J9 -> 0 | S9: =Science!K9 -> 0 | T9: =Science!L9 -> 0 | U9: =Science!M9 -> 0 | V9: =Science!N9 -> 0 | W9: =Maths!G9 -> 0 | X9: =Maths!H9 -> 0 | Y9: =Maths!I9 -> 0 | Z9: =IF(Y9>=90.5,"A*",IF(Y9>=79.5,"A",IF(Y9>=64.5,"B",IF(Y9>=49.5,"C",IF(Y9>=34.5,"D","E"))))) -> E | AA9: =Maths!J9 -> 0 | AB9: =Maths!K9 -> 0 | AC9: =Maths!L9 -> 0 | AD9: =Maths!M9 -> 0 | AE9: =Maths!N9 -> 0
A10: 6 | E10: =ESL!G10 -> 0 | F10: =ESL!K10 -> #DIV/0! | G10: =ESL!L10 -> #DIV/0! | H10: =IF(G10>=90.5,"A*",IF(G10>=79.5,"A",IF(G10>=64.5,"B",IF(G10>=49.5,"C",IF(G10>=34.5,"D","E"))))) -> #DIV/0! | I10: =ESL!M10 -> 0 | J10: =ESL!N10 -> 0 | K10: =ESL!O10 -> 0 | L10: =ESL!P10 -> 0 | M10: =ESL!Q10 -> 0 | N10: =Science!G10 -> 0 | O10: =Science!H10 -> 0 | P10: =Science!I10 -> 0 | Q10: =IF(P10>=90.5,"A*",IF(P10>=79.5,"A",IF(P10>=64.5,"B",IF(P10>=49.5,"C",IF(P10>=34.5,"D","E"))))) -> E | R10: =Science!J10 -> 0 | S10: =Science!K10 -> 0 | T10: =Science!L10 -> 0 | U10: =Science!M10 -> 0 | V10: =Science!N10 -> 0 | W10: =Maths!G10 -> 0 | X10: =Maths!H10 -> 0 | Y10: =Maths!I10 -> 0 | Z10: =IF(Y10>=90.5,"A*",IF(Y10>=79.5,"A",IF(Y10>=64.5,"B",IF(Y10>=49.5,"C",IF(Y10>=34.5,"D","E"))))) -> E | AA10: =Maths!J10 -> 0 | AB10: =Maths!K10 -> 0 | AC10: =Maths!L10 -> 0 | AD10: =Maths!M10 -> 0 | AE10: =Maths!N10 -> 0
A11: 7 | E11: =ESL!G11 -> 0 | F11: =ESL!K11 -> #DIV/0! | G11: =ESL!L11 -> #DIV/0! | H11: =IF(G11>=90.5,"A*",IF(G11>=79.5,"A",IF(G11>=64.5,"B",IF(G11>=49.5,"C",IF(G11>=34.5,"D","E"))))) -> #DIV/0! | I11: =ESL!M11 -> 0 | J11: =ESL!N11 -> 0 | K11: =ESL!O11 -> 0 | L11: =ESL!P11 -> 0 | M11: =ESL!Q11 -> 0 | N11: =Science!G11 -> 0 | O11: =Science!H11 -> 0 | P11: =Science!I11 -> 0 | Q11: =IF(P11>=90.5,"A*",IF(P11>=79.5,"A",IF(P11>=64.5,"B",IF(P11>=49.5,"C",IF(P11>=34.5,"D","E"))))) -> E | R11: =Science!J11 -> 0 | S11: =Science!K11 -> 0 | T11: =Science!L11 -> 0 | U11: =Science!M11 -> 0 | V11: =Science!N11 -> 0 | W11: =Maths!G11 -> 0 | X11: =Maths!H11 -> 0 | Y11: =Maths!I11 -> 0 | Z11: =IF(Y11>=90.5,"A*",IF(Y11>=79.5,"A",IF(Y11>=64.5,"B",IF(Y11>=49.5,"C",IF(Y11>=34.5,"D","E"))))) -> E | AA11: =Maths!J11 -> 0 | AB11: =Maths!K11 -> 0 | AC11: =Maths!L11 -> 0 | AD11: =Maths!M11 -> 0 | AE11: =Maths!N11 -> 0
A12: 8 | E12: =ESL!G12 -> 0 | F12: =ESL!K12 -> #DIV/0! | G12: =ESL!L12 -> #DIV/0! | H12: =IF(G12>=90.5,"A*",IF(G12>=79.5,"A",IF(G12>=64.5,"B",IF(G12>=49.5,"C",IF(G12>=34.5,"D","E"))))) -> #DIV/0! | I12: =ESL!M12 -> 0 | J12: =ESL!N12 -> 0 | K12: =ESL!O12 -> 0 | L12: =ESL!P12 -> 0 | M12: =ESL!Q12 -> 0 | N12: =Science!G12 -> 0 | O12: =Science!H12 -> 0 | P12: =Science!I12 -> 0 | Q12: =IF(P12>=90.5,"A*",IF(P12>=79.5,"A",IF(P12>=64.5,"B",IF(P12>=49.5,"C",IF(P12>=34.5,"D","E"))))) -> E | R12: =Science!J12 -> 0 | S12: =Science!K12 -> 0 | T12: =Science!L12 -> 0 | U12: =Science!M12 -> 0 | V12: =Science!N12 -> 0 | W12: =Maths!G12 -> 0 | X12: =Maths!H12 -> 0 | Y12: =Maths!I12 -> 0 | Z12: =IF(Y12>=90.5,"A*",IF(Y12>=79.5,"A",IF(Y12>=64.5,"B",IF(Y12>=49.5,"C",IF(Y12>=34.5,"D","E"))))) -> E | AA12: =Maths!J12 -> 0 | AB12: =Maths!K12 -> 0 | AC12: =Maths!L12 -> 0 | AD12: =Maths!M12 -> 0 | AE12: =Maths!N12 -> 0
A13: 9 | E13: =ESL!G13 -> 0 | F13: =ESL!K13 -> #DIV/0! | G13: =ESL!L13 -> #DIV/0! | H13: =IF(G13>=90.5,"A*",IF(G13>=79.5,"A",IF(G13>=64.5,"B",IF(G13>=49.5,"C",IF(G13>=34.5,"D","E"))))) -> #DIV/0! | I13: =ESL!M13 -> 0 | J13: =ESL!N13 -> 0 | K13: =ESL!O13 -> 0 | L13: =ESL!P13 -> 0 | M13: =ESL!Q13 -> 0 | N13: =Science!G13 -> 0 | O13: =Science!H13 -> 0 | P13: =Science!I13 -> 0 | Q13: =IF(P13>=90.5,"A*",IF(P13>=79.5,"A",IF(P13>=64.5,"B",IF(P13>=49.5,"C",IF(P13>=34.5,"D","E"))))) -> E | R13: =Science!J13 -> 0 | S13: =Science!K13 -> 0 | T13: =Science!L13 -> 0 | U13: =Science!M13 -> 0 | V13: =Science!N13 -> 0 | W13: =Maths!G13 -> 0 | X13: =Maths!H13 -> 0 | Y13: =Maths!I13 -> 0 | Z13: =IF(Y13>=90.5,"A*",IF(Y13>=79.5,"A",IF(Y13>=64.5,"B",IF(Y13>=49.5,"C",IF(Y13>=34.5,"D","E"))))) -> E | AA13: =Maths!J13 -> 0 | AB13: =Maths!K13 -> 0 | AC13: =Maths!L13 -> 0 | AD13: =Maths!M13 -> 0 | AE13: =Maths!N13 -> 0
A14: 10 | E14: =ESL!G14 -> 0 | F14: =ESL!K14 -> #DIV/0! | G14: =ESL!L14 -> #DIV/0! | H14: =IF(G14>=90.5,"A*",IF(G14>=79.5,"A",IF(G14>=64.5,"B",IF(G14>=49.5,"C",IF(G14>=34.5,"D","E"))))) -> #DIV/0! | I14: =ESL!M14 -> 0 | J14: =ESL!N14 -> 0 | K14: =ESL!O14 -> 0 | L14: =ESL!P14 -> 0 | M14: =ESL!Q14 -> 0 | N14: =Science!G14 -> 0 | O14: =Science!H14 -> 0 | P14: =Science!I14 -> 0 | Q14: =IF(P14>=90.5,"A*",IF(P14>=79.5,"A",IF(P14>=64.5,"B",IF(P14>=49.5,"C",IF(P14>=34.5,"D","E"))))) -> E | R14: =Science!J14 -> 0 | S14: =Science!K14 -> 0 | T14: =Science!L14 -> 0 | U14: =Science!M14 -> 0 | V14: =Science!N14 -> 0 | W14: =Maths!G14 -> 0 | X14: =Maths!H14 -> 0 | Y14: =Maths!I14 -> 0 | Z14: =IF(Y14>=90.5,"A*",IF(Y14>=79.5,"A",IF(Y14>=64.5,"B",IF(Y14>=49.5,"C",IF(Y14>=34.5,"D","E"))))) -> E | AA14: =Maths!J14 -> 0 | AB14: =Maths!K14 -> 0 | AC14: =Maths!L14 -> 0 | AD14: =Maths!M14 -> 0 | AE14: =Maths!N14 -> 0
A15: 11 | E15: =ESL!G15 -> 0 | F15: =ESL!K15 -> #DIV/0! | G15: =ESL!L15 -> #DIV/0! | H15: =IF(G15>=90.5,"A*",IF(G15>=79.5,"A",IF(G15>=64.5,"B",IF(G15>=49.5,"C",IF(G15>=34.5,"D","E"))))) -> #DIV/0! | I15: =ESL!M15 -> 0 | J15: =ESL!N15 -> 0 | K15: =ESL!O15 -> 0 | L15: =ESL!P15 -> 0 | M15: =ESL!Q15 -> 0 | N15: =Science!G15 -> 0 | O15: =Science!H15 -> 0 | P15: =Science!I15 -> 0 | Q15: =IF(P15>=90.5,"A*",IF(P15>=79.5,"A",IF(P15>=64.5,"B",IF(P15>=49.5,"C",IF(P15>=34.5,"D","E"))))) -> E | R15: =Science!J15 -> 0 | S15: =Science!K15 -> 0 | T15: =Science!L15 -> 0 | U15: =Science!M15 -> 0 | V15: =Science!N15 -> 0 | W15: =Maths!G15 -> 0 | X15: =Maths!H15 -> 0 | Y15: =Maths!I15 -> 0 | Z15: =IF(Y15>=90.5,"A*",IF(Y15>=79.5,"A",IF(Y15>=64.5,"B",IF(Y15>=49.5,"C",IF(Y15>=34.5,"D","E"))))) -> E | AA15: =Maths!J15 -> 0 | AB15: =Maths!K15 -> 0 | AC15: =Maths!L15 -> 0 | AD15: =Maths!M15 -> 0 | AE15: =Maths!N15 -> 0
A16: 12 | E16: =ESL!G16 -> 0 | F16: =ESL!K16 -> #DIV/0! | G16: =ESL!L16 -> #DIV/0! | H16: =IF(G16>=90.5,"A*",IF(G16>=79.5,"A",IF(G16>=64.5,"B",IF(G16>=49.5,"C",IF(G16>=34.5,"D","E"))))) -> #DIV/0! | I16: =ESL!M16 -> 0 | J16: =ESL!N16 -> 0 | K16: =ESL!O16 -> 0 | L16: =ESL!P16 -> 0 | M16: =ESL!Q16 -> 0 | N16: =Science!G16 -> 0 | O16: =Science!H16 -> 0 | P16: =Science!I16 -> 0 | Q16: =IF(P16>=90.5,"A*",IF(P16>=79.5,"A",IF(P16>=64.5,"B",IF(P16>=49.5,"C",IF(P16>=34.5,"D","E"))))) -> E | R16: =Science!J16 -> 0 | S16: =Science!K16 -> 0 | T16: =Science!L16 -> 0 | U16: =Science!M16 -> 0 | V16: =Science!N16 -> 0 | W16: =Maths!G16 -> 0 | X16: =Maths!H16 -> 0 | Y16: =Maths!I16 -> 0 | Z16: =IF(Y16>=90.5,"A*",IF(Y16>=79.5,"A",IF(Y16>=64.5,"B",IF(Y16>=49.5,"C",IF(Y16>=34.5,"D","E"))))) -> E | AA16: =Maths!J16 -> 0 | AB16: =Maths!K16 -> 0 | AC16: =Maths!L16 -> 0 | AD16: =Maths!M16 -> 0 | AE16: =Maths!N16 -> 0
... A34: 30 | E34: =ESL!G34 -> 0 | F34: =ESL!K34 -> #DIV/0! | G34: =ESL!L34 -> #DIV/0! | H34: =IF(G34>=90.5,"A*",IF(G34>=79.5,"A",IF(G34>=64.5,"B",IF(G34>=49.5,"C",IF(G34>=34.5,"D","E"))))) -> #DIV/0! | I34: =ESL!M34 -> 0 | J34: =ESL!N34 -> 0 | K34: =ESL!O34 -> 0 | L34: =ESL!P34 -> 0 | M34: =ESL!Q34 -> 0 | N34: =Science!G34 -> 0 | O34: =Science!H34 -> 0 | P34: =Science!I34 -> 0 | Q34: =IF(P34>=90.5,"A*",IF(P34>=79.5,"A",IF(P34>=64.5,"B",IF(P34>=49.5,"C",IF(P34>=34.5,"D","E"))))) -> E | R34: =Science!J34 -> 0 | S34: =Science!K34 -> 0 | T34: =Science!L34 -> 0 | U34: =Science!M34 -> 0 | V34: =Science!N34 -> 0 | W34: =Maths!G34 -> 0 | X34: =Maths!H34 -> 0 | Y34: =Maths!I34 -> 0 | Z34: =IF(Y34>=90.5,"A*",IF(Y34>=79.5,"A",IF(Y34>=64.5,"B",IF(Y34>=49.5,"C",IF(Y34>=34.5,"D","E"))))) -> E | AA34: =Maths!J34 -> 0 | AB34: =Maths!K34 -> 0 | AC34: =Maths!L34 -> 0 | AD34: =Maths!M34 -> 0 | AE34: =Maths!N34 -> 0
B37: Percentage | C37: Graded | D37: Ranking
B38: 100 | C38: A* | D38: Excellent | E38: Xuất sắc
B39: =B38-0.5 -> 99.5 | C39: A* | D39: Excellent
B40: =B39-0.5 -> 99 | C40: A* | D40: Excellent
B41: =B40-0.5 -> 98.5 | C41: A* | D41: Excellent
B42: =B41-0.5 -> 98 | C42: A* | D42: Excellent
B43: =B42-0.5 -> 97.5 | C43: A* | D43: Excellent
B44: =B43-0.5 -> 97 | C44: A* | D44: Excellent
B45: =B44-0.5 -> 96.5 | C45: A* | D45: Excellent
B46: =B45-0.5 -> 96 | C46: A* | D46: Excellent
B47: =B46-0.5 -> 95.5 | C47: A* | D47: Excellent
B48: =B47-0.5 -> 95 | C48: A* | D48: Excellent
B49: =B48-0.5 -> 94.5 | C49: A* | D49: Excellent
B50: =B49-0.5 -> 94 | C50: A* | D50: Excellent
... B57: =B56-0.5 -> 90.5 | C57: A* | D57: Excellent
B58: =B57-0.5 -> 90 | C58: A | D58: Very Good | E58: Giỏi
B59: =B58-0.5 -> 89.5 | C59: A | D59: Very Good
B60: =B59-0.5 -> 89 | C60: A | D60: Very Good
B61: =B60-0.5 -> 88.5 | C61: A | D61: Very Good
B62: =B61-0.5 -> 88 | C62: A | D62: Very Good
B63: =B62-0.5 -> 87.5 | C63: A | D63: Very Good
B64: =B63-0.5 -> 87 | C64: A | D64: Very Good
B65: =B64-0.5 -> 86.5 | C65: A | D65: Very Good
...

Sheet ESL
A1: =CLASS!A1 -> ROYAL INTERNATIONAL BILINGUAL SCHOOL ACADEMIC YEAR: 2026 - 2027
A3: CLASS | B3: =CLASS!B3 -> 0 | C3: Student Name | E3: Participation | F3: Marked Assignments | G3: Attainment Score | H3: Listening | I3: Reading & Writing | J3: Speaking | K3: Progress Test | L3: Overal Score | M3: Confident | N3: Responsible | O3: Reflective | P3: Innovative | Q3: Engaged | R3: Comments
A4: STT | B4: Student ID | C4: Name (VN) | D4: Name (ENG) | E4: 1 | F4: 2 | H4: 3 | I4: 4 | J4: 5
A5: 1 | B5: =CLASS!B5 -> 0 | C5: =CLASS!C5 -> 0 | D5: =CLASS!D5 -> 0 | G5: =E5*0.2+F5*0.8 -> 0 | K5: =AVERAGE(H5:J5) -> #DIV/0! | L5: =G5*0.75+K5*0.25 -> #DIV/0!
A6: 2 | B6: =CLASS!B6 -> 0 | C6: =CLASS!C6 -> 0 | D6: =CLASS!D6 -> 0 | G6: =E6*0.2+F6*0.8 -> 0 | K6: =AVERAGE(H6:J6) -> #DIV/0! | L6: =G6*0.75+K6*0.25 -> #DIV/0!
A7: 3 | B7: =CLASS!B7 -> 0 | C7: =CLASS!C7 -> 0 | D7: =CLASS!D7 -> 0 | G7: =E7*0.2+F7*0.8 -> 0 | K7: =AVERAGE(H7:J7) -> #DIV/0! | L7: =G7*0.75+K7*0.25 -> #DIV/0!
A8: 4 | B8: =CLASS!B8 -> 0 | C8: =CLASS!C8 -> 0 | D8: =CLASS!D8 -> 0 | G8: =E8*0.2+F8*0.8 -> 0 | K8: =AVERAGE(H8:J8) -> #DIV/0! | L8: =G8*0.75+K8*0.25 -> #DIV/0!
A9: 5 | B9: =CLASS!B9 -> 0 | C9: =CLASS!C9 -> 0 | D9: =CLASS!D9 -> 0 | G9: =E9*0.2+F9*0.8 -> 0 | K9: =AVERAGE(H9:J9) -> #DIV/0! | L9: =G9*0.75+K9*0.25 -> #DIV/0!
A10: 6 | B10: =CLASS!B10 -> 0 | C10: =CLASS!C10 -> 0 | D10: =CLASS!D10 -> 0 | G10: =E10*0.2+F10*0.8 -> 0 | K10: =AVERAGE(H10:J10) -> #DIV/0! | L10: =G10*0.75+K10*0.25 -> #DIV/0!
A11: 7 | B11: =CLASS!B11 -> 0 | C11: =CLASS!C11 -> 0 | D11: =CLASS!D11 -> 0 | G11: =E11*0.2+F11*0.8 -> 0 | K11: =AVERAGE(H11:J11) -> #DIV/0! | L11: =G11*0.75+K11*0.25 -> #DIV/0!
A12: 8 | B12: =CLASS!B12 -> 0 | C12: =CLASS!C12 -> 0 | D12: =CLASS!D12 -> 0 | G12: =E12*0.2+F12*0.8 -> 0 | K12: =AVERAGE(H12:J12) -> #DIV/0! | L12: =G12*0.75+K12*0.25 -> #DIV/0!
A13: 9 | B13: =CLASS!B13 -> 0 | C13: =CLASS!C13 -> 0 | D13: =CLASS!D13 -> 0 | G13: =E13*0.2+F13*0.8 -> 0 | K13: =AVERAGE(H13:J13) -> #DIV/0! | L13: =G13*0.75+K13*0.25 -> #DIV/0!
A14: 10 | B14: =CLASS!B14 -> 0 | C14: =CLASS!C14 -> 0 | D14: =CLASS!D14 -> 0 | G14: =E14*0.2+F14*0.8 -> 0 | K14: =AVERAGE(H14:J14) -> #DIV/0! | L14: =G14*0.75+K14*0.25 -> #DIV/0!
A15: 11 | B15: =CLASS!B15 -> 0 | C15: =CLASS!C15 -> 0 | D15: =CLASS!D15 -> 0 | G15: =E15*0.2+F15*0.8 -> 0 | K15: =AVERAGE(H15:J15) -> #DIV/0! | L15: =G15*0.75+K15*0.25 -> #DIV/0!
A16: 12 | B16: =CLASS!B16 -> 0 | C16: =CLASS!C16 -> 0 | D16: =CLASS!D16 -> 0 | G16: =E16*0.2+F16*0.8 -> 0 | K16: =AVERAGE(H16:J16) -> #DIV/0! | L16: =G16*0.75+K16*0.25 -> #DIV/0!
... A34: 30 | B34: =CLASS!B34 -> 0 | C34: =CLASS!C34 -> 0 | D34: =CLASS!D34 -> 0 | G34: =E34*0.2+F34*0.8 -> 0 | K34: =AVERAGE(H34:J34) -> #DIV/0! | L34: =G34*0.75+K34*0.25 -> #DIV/0!

Sheet Maths
A1: =CLASS!A1 -> ROYAL INTERNATIONAL BILINGUAL SCHOOL ACADEMIC YEAR: 2026 - 2027
A3: CLASS | B3: =CLASS!B3 -> 0 | C3: Student Name | E3: Participation | F3: Marked Assignments | G3: Attainment Score | H3: Progress Test | I3: Overal Score | J3: Confident | K3: Responsible | L3: Reflective | M3: Innovative | N3: Engaged | O3: Comments
A4: STT | B4: Student ID | C4: Name (VN) | D4: Name (ENG) | E4: 1 | F4: 2 | H4: 3
A5: 1 | B5: =CLASS!B5 -> 0 | C5: =CLASS!C5 -> 0 | D5: =CLASS!D5 -> 0 | G5: =E5*0.2+F5*0.8 -> 0 | I5: =G5*0.75+H5*0.25 -> 0
A6: 2 | B6: =CLASS!B6 -> 0 | C6: =CLASS!C6 -> 0 | D6: =CLASS!D6 -> 0 | G6: =E6*0.2+F6*0.8 -> 0 | I6: =G6*0.75+H6*0.25 -> 0
A7: 3 | B7: =CLASS!B7 -> 0 | C7: =CLASS!C7 -> 0 | D7: =CLASS!D7 -> 0 | G7: =E7*0.2+F7*0.8 -> 0 | I7: =G7*0.75+H7*0.25 -> 0
A8: 4 | B8: =CLASS!B8 -> 0 | C8: =CLASS!C8 -> 0 | D8: =CLASS!D8 -> 0 | G8: =E8*0.2+F8*0.8 -> 0 | I8: =G8*0.75+H8*0.25 -> 0
A9: 5 | B9: =CLASS!B9 -> 0 | C9: =CLASS!C9 -> 0 | D9: =CLASS!D9 -> 0 | G9: =E9*0.2+F9*0.8 -> 0 | I9: =G9*0.75+H9*0.25 -> 0
A10: 6 | B10: =CLASS!B10 -> 0 | C10: =CLASS!C10 -> 0 | D10: =CLASS!D10 -> 0 | G10: =E10*0.2+F10*0.8 -> 0 | I10: =G10*0.75+H10*0.25 -> 0
A11: 7 | B11: =CLASS!B11 -> 0 | C11: =CLASS!C11 -> 0 | D11: =CLASS!D11 -> 0 | G11: =E11*0.2+F11*0.8 -> 0 | I11: =G11*0.75+H11*0.25 -> 0
A12: 8 | B12: =CLASS!B12 -> 0 | C12: =CLASS!C12 -> 0 | D12: =CLASS!D12 -> 0 | G12: =E12*0.2+F12*0.8 -> 0 | I12: =G12*0.75+H12*0.25 -> 0
A13: 9 | B13: =CLASS!B13 -> 0 | C13: =CLASS!C13 -> 0 | D13: =CLASS!D13 -> 0 | G13: =E13*0.2+F13*0.8 -> 0 | I13: =G13*0.75+H13*0.25 -> 0
A14: 10 | B14: =CLASS!B14 -> 0 | C14: =CLASS!C14 -> 0 | D14: =CLASS!D14 -> 0 | G14: =E14*0.2+F14*0.8 -> 0 | I14: =G14*0.75+H14*0.25 -> 0
A15: 11 | B15: =CLASS!B15 -> 0 | C15: =CLASS!C15 -> 0 | D15: =CLASS!D15 -> 0 | G15: =E15*0.2+F15*0.8 -> 0 | I15: =G15*0.75+H15*0.25 -> 0
A16: 12 | B16: =CLASS!B16 -> 0 | C16: =CLASS!C16 -> 0 | D16: =CLASS!D16 -> 0 | G16: =E16*0.2+F16*0.8 -> 0 | I16: =G16*0.75+H16*0.25 -> 0
... A34: 30 | B34: =CLASS!B34 -> 0 | C34: =CLASS!C34 -> 0 | D34: =CLASS!D34 -> 0 | G34: =E34*0.2+F34*0.8 -> 0 | I34: =G34*0.75+H34*0.25 -> 0

Sheet Science
A1: =CLASS!A1 -> ROYAL INTERNATIONAL BILINGUAL SCHOOL ACADEMIC YEAR: 2026 - 2027
A3: CLASS | B3: =CLASS!B3 -> 0 | C3: Student Name | E3: Participation | F3: Marked Assignments | G3: Attainment Score | H3: Progress Test | I3: Overal Score | J3: Confident | K3: Responsible | L3: Reflective | M3: Innovative | N3: Engaged | O3: Comments
A4: STT | B4: Student ID | C4: Name (VN) | D4: Name (ENG) | E4: 1 | F4: 2 | H4: 3
A5: 1 | B5: =CLASS!B5 -> 0 | C5: =CLASS!C5 -> 0 | D5: =CLASS!D5 -> 0 | G5: =E5*0.2+F5*0.8 -> 0 | I5: =G5*0.75+H5*0.25 -> 0
A6: 2 | B6: =CLASS!B6 -> 0 | C6: =CLASS!C6 -> 0 | D6: =CLASS!D6 -> 0 | G6: =E6*0.2+F6*0.8 -> 0 | I6: =G6*0.75+H6*0.25 -> 0
A7: 3 | B7: =CLASS!B7 -> 0 | C7: =CLASS!C7 -> 0 | D7: =CLASS!D7 -> 0 | G7: =E7*0.2+F7*0.8 -> 0 | I7: =G7*0.75+H7*0.25 -> 0
A8: 4 | B8: =CLASS!B8 -> 0 | C8: =CLASS!C8 -> 0 | D8: =CLASS!D8 -> 0 | G8: =E8*0.2+F8*0.8 -> 0 | I8: =G8*0.75+H8*0.25 -> 0
A9: 5 | B9: =CLASS!B9 -> 0 | C9: =CLASS!C9 -> 0 | D9: =CLASS!D9 -> 0 | G9: =E9*0.2+F9*0.8 -> 0 | I9: =G9*0.75+H9*0.25 -> 0
A10: 6 | B10: =CLASS!B10 -> 0 | C10: =CLASS!C10 -> 0 | D10: =CLASS!D10 -> 0 | G10: =E10*0.2+F10*0.8 -> 0 | I10: =G10*0.75+H10*0.25 -> 0
A11: 7 | B11: =CLASS!B11 -> 0 | C11: =CLASS!C11 -> 0 | D11: =CLASS!D11 -> 0 | G11: =E11*0.2+F11*0.8 -> 0 | I11: =G11*0.75+H11*0.25 -> 0
A12: 8 | B12: =CLASS!B12 -> 0 | C12: =CLASS!C12 -> 0 | D12: =CLASS!D12 -> 0 | G12: =E12*0.2+F12*0.8 -> 0 | I12: =G12*0.75+H12*0.25 -> 0
A13: 9 | B13: =CLASS!B13 -> 0 | C13: =CLASS!C13 -> 0 | D13: =CLASS!D13 -> 0 | G13: =E13*0.2+F13*0.8 -> 0 | I13: =G13*0.75+H13*0.25 -> 0
A14: 10 | B14: =CLASS!B14 -> 0 | C14: =CLASS!C14 -> 0 | D14: =CLASS!D14 -> 0 | G14: =E14*0.2+F14*0.8 -> 0 | I14: =G14*0.75+H14*0.25 -> 0
A15: 11 | B15: =CLASS!B15 -> 0 | C15: =CLASS!C15 -> 0 | D15: =CLASS!D15 -> 0 | G15: =E15*0.2+F15*0.8 -> 0 | I15: =G15*0.75+H15*0.25 -> 0
A16: 12 | B16: =CLASS!B16 -> 0 | C16: =CLASS!C16 -> 0 | D16: =CLASS!D16 -> 0 | G16: =E16*0.2+F16*0.8 -> 0 | I16: =G16*0.75+H16*0.25 -> 0
... A34: 30 | B34: =CLASS!B34 -> 0 | C34: =CLASS!C34 -> 0 | D34: =CLASS!D34 -> 0 | G34: =E34*0.2+F34*0.8 -> 0 | I34: =G34*0.75+H34*0.25 -> 0

Sheet Repord Card Template
B3: STUDENT REPORT | P3: Assessment Scale
B5: Mid Term 1/ School-year: 2023 - 2024
P6: Excellent A* | Q6: 91 – 100% | R6: The student has an exemplary knowledge and understanding of the content and can readily apply this knowledge. In addition, the student has achieved a very high level of competence in the processes and skills and can apply these skills to new situations.
A7: Full Name: | D7: =CLASS!C5 -> 0 | N7: Grade: | O7: =CLASS!B3 -> 0
A8: Student ID: | D8: =CLASS!B5 -> 0
A10: ESL | B10: Participation | C10: Marked Assignments | D10: Attainment scores | E10: Listening | F10: Reading & Writing | G10: Speaking | H10: Progression Test | I10: Overall Scores | J10: Grade | K10: Learning Skills and Work Habits | P10: Very Good A | Q10: 80 – 90% | R10: The student has a thorough knowledge and understanding of the content and an accomplished level of competence in the processes and skills. In addition, the student is able to apply this knowledge and these skills to most situations.
K11: Confident | L11: Responsible | M11: Reflective | N11: Innovative | O11: Engaged
A12: Teacher: | P12: Good B | Q12: 65 - 79% | R12: The student has a sound knowledge and understanding of the main areas of content and has achieved an adequate level of competence in the processes and skills.
A13: =ESL!R2 -> 0 | K13: =ESL!M5 -> 0 | L13: =ESL!N5 -> 0 | M13: =ESL!O5 -> 0 | N13: =ESL!P5 -> 0 | O13: =ESL!Q5 -> 0
A14: Insert Comments here | P14: Average C | Q14: 50 - 65% | R14: The student has a fundamental knowledge and understanding of the main areas of content and has achieved an acceptable level of competence in the processes and skills.
A15: SCIENCE | B15: Participation | C15: Marked Assignments | D15: Attainment scores | F15: Progression Test | H15: Overall Scores | J15: Grade | K15: Learning Skills and Work Habits
K16: Confident | L16: Responsible | M16: Reflective | N16: Innovative | O16: Engaged
A17: Teacher: | P17: Minimal D | Q17: 35 – 49% | R17: The student has a basic knowledge and understanding of the content and has achieved a limited level of competence in the processes and skills.
A18: =Science!O2 -> 0 | K18: =Science!J5 -> 0 | L18: =Science!K5 -> 0 | M18: =Science!L5 -> 0 | N18: =Science!M5 -> 0 | O18: =Science!N5 -> 0
A19: Insert Comments here | P19: Emerging E | Q19: 0 – 34% | R19: The student has a developing knowledge and understanding in few areas of the content and has achieved very limited competence in some of the processes and skills.
A20: MATHEMATICS | B20: Participation | C20: Marked Assignments | D20: Attainment scores | F20: Progression Test | H20: Overall Scores | J20: Grade | K20: Learning Skills and Work Habits
K21: Confident | L21: Responsible | M21: Reflective | N21: Innovative | O21: Engaged
A22: Teacher:
A23: =Maths!O2 -> 0 | K23: =CLASS!AA5 -> 0 | L23: =CLASS!AB5 -> 0 | M23: =CLASS!AC5 -> 0 | N23: =CLASS!AD5 -> 0 | O23: =CLASS!AE5 -> 0 | P23: Learning Skills and Work Habits G – Good S – Satisfied N - Need improving
A24: Insert Comments here
P26: Confident | Q26: Confident in working with information and ideas – their own and those of others
P28: Responsible | Q28: Responsible for themselves, responsive to and respectful of others
A30: Ho Chi Minh City, …………………, 2023 | P30: Reflective | Q30: Reflective as learners, developing their ability to learn
A32: Deputy Director of International Curriculum Training Centre | J32: Principal/ Hiệu Trưởng | P32: Innovative | Q32: Innovative and equipped for new and future challenges
P34: Engaged | Q34: Engaged intellectually and socially, ready to make a difference
A35: Donovan Cedric Rogiers | J35: Mai Duc Thang
